<?xml version="1.0"?>
<robot name="visual">

<material name="blue">
    <color rgba="0 0 .8 1"/>
  </material>
  <material name="black">
    <color rgba="0 0 0 1"/>
  </material>
  <material name="white">
    <color rgba="1 1 1 1"/>
  </material>
  <material name="green">
    <color rgba="0 1 0 1"/>
  </material>
  <material name="red">
    <color rgba="1 0 0 1"/>
  </material>

  <link name="base_link">
    <visual>
      <geometry>
        <box size="3.0 2.0 0.1"/>
      </geometry>
      <material name="blue"/>
    </visual>
  </link>

  <link name="arm">
    <visual>
      <geometry>
        <box size="0.1 0.5 3.0"/>
      </geometry>
      <origin rpy="0 0 0" xyz="0 0 1.5"/>
      <material name="red"/>
    </visual>
  </link>

  <joint name="base_to_arm" type="continuous">
    <parent link="base_link"/>
    <child link="arm"/>
    <axis xyz="0 1 0"/>
    <origin xyz="-1.5 0 0"/>
  </joint>

  <link name="head">
    <visual>
      <geometry>
        <box size="1.0 0.5 0.1"/>
      </geometry>
      <origin rpy="0 0 0" xyz="-0.5 0 0"/>
      <material name="green"/>
    </visual>
  </link>

  <joint name="arm_to_head" type="continuous">
    <parent link="arm"/>
    <child link="head"/>
    <origin xyz="0 0 3.0"/>
    <axis xyz="0 1.0 0"/>
  </joint>

  <link name="camera">
    <visual>
      <geometry>
        <cylinder length="0.5" radius="0.1" />
      </geometry>
      <origin rpy="1.57 0 1.57" xyz="-0.25 0 0"/>
      <material name="blue"/>
    </visual>
  </link>

  <joint name="head_to_camera" type="continuous">
    <parent link="head"/>
    <child link="camera"/>
    <origin xyz="-1.0 0 0"/>
    <axis xyz="0 0 1"/>
  </joint>






</robot>
